Workbook

Sheet Worksheet
A1: ID | B1: Naam | C1: Voornaam | E1: Geslacht | F1: Geboortedatum | G1: Straat | H1: Huisnummer | I1: Busnummer | J1: Postcode | K1: Gemeente | L1: Land | M1: Nationaliteit | N1: Beroep | O1: E-mail 1 type | P1: E-mail 1 | Q1: E-mail 2 type | R1: E-mail 2 | S1: E-mail 3 type | T1: E-mail 3 | U1: Mobiel 1 type | V1: Mobiel 1 | W1: Mobiel 2 type | X1: Mobiel 2 | Y1: Mobiel 3 type | Z1: Mobiel 3 | AA1: Telefoon | AB1: Rekeningnummer | AC1: Rijksregisternummer | AD1: Rugnummer | AE1: Profielfoto | AF1: Relation ID invoicing (Export / Octopus) | AG1: Lidnummer Basket Vlaanderen | AH1: Club name | AI1: Club function | AJ1: 2026-2027 | AK1: 2026-2027 Functie | AL1: Committee
A2: 5559997 | B2: Adam | C2: Koen | D2: nl | E2: M | F2: 07/05/1978 | G2: Braambrugstraat | H2: 26 | J2: 9700 | K2: Oudenaarde | L2: Belgium | M2: BE | O2: Persoonlijk | P2: koenadam78@gmail.com | AF2: 1005559997
A3: 2182441 | B3: Adam | C3: Lily | D3: nl | E3: F | F3: 07/05/2010 | G3: Braambrugstraat | H3: 26 | Q3: Vader | R3: Koenadam78@gmail.com | S3: Moeder | T3: Freya.spiessens@gmail.com | V3: 0476837352 | W3: Dochter | X3: 0456558867 | Y3: Vader | Z3: 0456558867 | AC3: 10.05.07-190.68 | AE3: https://app.twizzit.com/public/photos/2182441/s/eec7946e1a9e80461f26752840c4aedc7d235bab.jpeg | AF3: 1002182441 | AG3: 728412 | AJ3: DSE A Haantjes Certifisc Oudenaarde | AK3: Speler | AL3: Clubrefs (Clubref)
A4: 2182441 | B4: Adam | C4: Lily | D4: nl | E4: F | F4: 07/05/2010 | G4: Braambrugstraat | H4: 26 | Q4: Vader | R4: Koenadam78@gmail.com | S4: Moeder | T4: Freya.spiessens@gmail.com | V4: 0476837352 | W4: Dochter | X4: 0456558867 | Y4: Vader | Z4: 0456558867 | AC4: 10.05.07-190.68 | AE4: https://app.twizzit.com/public/photos/2182441/s/eec7946e1a9e80461f26752840c4aedc7d235bab.jpeg | AF4: 1002182441 | AG4: 728412 | AJ4: Zomerstage 2026 (Blankenberge) | AK4: Speler | AL4: Clubrefs (Clubref)
A5: 2182441 | B5: Adam | C5: Lily | D5: nl | E5: F | F5: 07/05/2010 | G5: Braambrugstraat | H5: 26 | Q5: Vader | R5: Koenadam78@gmail.com | S5: Moeder | T5: Freya.spiessens@gmail.com | V5: 0476837352 | W5: Dochter | X5: 0456558867 | Y5: Vader | Z5: 0456558867 | AC5: 10.05.07-190.68 | AE5: https://app.twizzit.com/public/photos/2182441/s/eec7946e1a9e80461f26752840c4aedc7d235bab.jpeg | AF5: 1002182441 | AG5: 728412 | AJ5: Trainerspoule | AK5: Coach | AL5: Clubrefs (Clubref)
A6: 5577896 | B6: Alia | C6: Enida | D6: nl | E6: F | F6: 22/05/2017 | G6: Broekstraat | H6: 133 | R6: elidona.eni@gmail.com | V6: 00499284650 | X6: 0 | Z6: 0 | AA6: 0 | AF6: 1005577896
A7: 2650601 | B7: Alia | C7: Kledion | D7: nl | E7: M | F7: 23/09/2013 | G7: Broekstraat | H7: 133 | U7: Vader | V7: 32499284650 | AE7: https://app.twizzit.com/public/photos/2650601/s/f885f644ea63bcfe0579c08cf537df8dcbb43ecc.png | AF7: 1002650601 | AG7: 742334 | AJ7: G14 A Haantjes CERTIFISC Oudenaarde | AK7: Speler | AL7: Clubrefs (Clubref)
A8: 5511777 | B8: Altruy | C8: Kors | D8: nl | E8: M | F8: 19/07/2014 | G8: Markettestraat | H8: 3 | Q8: Vader | R8: David.altruy@outlook.be | V8: 0479873979 | W8: Vader | X8: 32475950308 | AC8: 14.07.19-211.76 | AF8: 1005511777 | AJ8: G14 B Haantjes CERTIFISC Oudenaarde | AK8: Speler
A9: 4499004 | B9: Altruy | C9: Lenn | D9: nl | E9: M | F9: 27/02/2017 | G9: Markettestraat | H9: 3 | Q9: Vader | R9: David.altruy@outlook.be | U9: Moeder | V9: 0479873979 | W9: Vader | X9: 32475950308 | AC9: 11.07.27-323.43 | AF9: 1004499004 | AJ9: Zomerstage 2026 U10 & U12 (Oudenaarde) | AK9: Speler
A10: 4499004 | B10: Altruy | C10: Lenn | D10: nl | E10: M | F10: 27/02/2017 | G10: Markettestraat | H10: 3 | Q10: Vader | R10: David.altruy@outlook.be | U10: Moeder | V10: 0479873979 | W10: Vader | X10: 32475950308 | AC10: 11.07.27-323.43 | AF10: 1004499004 | AJ10: G10 Geel HAANTJES CERTIFISC OUDENAARDE | AK10: Speler
A11: 5115343 | B11: Ameloot-Vanhove | C11: Isa | D11: nl | E11: F | F11: 22/02/2012 | G11: Baarstraat | H11: 52 | R11: sofie.ameloot@huurland.be | U11: Moeder | V11: 0483203613 | W11: Moeder | X11: 0478210216 | AE11: https://app.twizzit.com/public/photos/5115343/s/0e6908415a8d44c9a80019c8bc87b39596577cc5.jpeg | AF11: 1005115343 | AJ11: M16 A Haantjes CERTIFISC Oudenaarde | AK11: Speler
A12: 11272034 | B12: Anar | C12: Arsen | D12: nl | E12: M | F12: 04/05/2016 | G12: Ohiostraat | H12: 203 | V12: 0 | X12: 0 | Z12: 0 | AA12: 0 | AC12: 16.05.04-489.82 | AE12: https://app.twizzit.com/public/photos/11272034/s/339c8f61eeb207a0a7ef82edab3f88fc90d76b77.jpeg | AF12: 1011272034 | AJ12: G12 Blauw HAANTJES CERTIFISC OUDENAARDE | AK12: Speler
A13: 11272030 | B13: Anar | C13: Mark | D13: nl | E13: M | F13: 04/05/2016 | G13: Ohiostraat | H13: 203 | AA13: 32495316150 | AC13: 16.05.04-491.80 | AE13: https://app.twizzit.com/public/photos/11272030/s/d97169c55e4278dd5f5452138091d993430ca8ab.jpeg | AF13: 1011272030 | AJ13: G12 Blauw HAANTJES CERTIFISC OUDENAARDE | AK13: Speler
A14: 11272039 | B14: Anar | C14: Marsel | D14: nl | E14: M | F14: 04/05/2016 | G14: Ohiostraat | H14: 203 | V14: 0 | X14: 0 | Z14: 0 | AA14: 0 | AC14: 16.05.04-493.78 | AE14: https://app.twizzit.com/public/photos/11272039/s/667db68e153309a064042452d0f619e8acb011fa.jpeg | AF14: 1011272039 | AJ14: G12 Blauw HAANTJES CERTIFISC OUDENAARDE | AK14: Speler
A15: 2182451 | B15: Anseeuw | C15: Bent | D15: nl | E15: M | F15: 30/06/2010 | G15: Dorpsstraat | H15: 62 | Q15: Zoon | R15: bent.anseeuw@gmail.com | U15: Moeder | V15: 0497023380 | X15: 0459412728 | AD15: 10 | AE15: https://app.twizzit.com/public/photos/2182451/s/d40702514c4affc118f06eee4555b1ca966c4e65.png | AF15: 1002182451 | AG15: 713666 | AJ15: J18 B Haantjes CERTIFISC Oudenaarde | AK15: Speler | AL15: Clubrefs (Clubref)
A16: 2182451 | B16: Anseeuw | C16: Bent | D16: nl | E16: M | F16: 30/06/2010 | G16: Dorpsstraat | H16: 62 | Q16: Zoon | R16: bent.anseeuw@gmail.com | U16: Moeder | V16: 0497023380 | X16: 0459412728 | AD16: 10 | AE16: https://app.twizzit.com/public/photos/2182451/s/d40702514c4affc118f06eee4555b1ca966c4e65.png | AF16: 1002182451 | AG16: 713666 | AJ16: Zomerstage 2026 (Blankenberge) | AK16: Speler | AL16: Clubrefs (Clubref)
A17: 2182456 | B17: Anseeuw | C17: Mare | D17: nl | E17: F | F17: 17/02/2014 | G17: Dorpstraat | H17: 62 | R17: matthias.anseeuw@telenet.be | V17: 497023380 | AC17: 14.02.17-334.75 | AE17: https://app.twizzit.com/public/photos/2182456/s/112b54676bd1e925e699cce3ec7a25a94902a3a2.png | AF17: 1002182456 | AG17: 735071 | AJ17: Zomerstage 2026 (Blankenberge) | AK17: Speler
A18: 2182456 | B18: Anseeuw | C18: Mare | D18: nl | E18: F | F18: 17/02/2014 | G18: Dorpstraat | H18: 62 | R18: matthias.anseeuw@telenet.be | V18: 497023380 | AC18: 14.02.17-334.75 | AE18: https://app.twizzit.com/public/photos/2182456/s/112b54676bd1e925e699cce3ec7a25a94902a3a2.png | AF18: 1002182456 | AG18: 735071 | AJ18: M14 A Haantjes CERTIFISC Oudenaarde | AK18: Speler
A19: 4421954 | B19: Anseeuw | C19: Senn | D19: nl | E19: M | F19: 15/05/2018 | G19: Dorpstraat | H19: 62 | Q19: Vader | R19: matthias.anseeuw@telenet.be | V19: 0497023380 | AE19: https://app.twizzit.com/public/photos/4421954/s/39c1d6c08bc84b336f4c340a175719810e926066.png | AF19: 1004421954 | AJ19: G10 Blauw HAANTJES CERTIFISC OUDENAARDE | AK19: Speler
A20: 4421954 | B20: Anseeuw | C20: Senn | D20: nl | E20: M | F20: 15/05/2018 | G20: Dorpstraat | H20: 62 | Q20: Vader | R20: matthias.anseeuw@telenet.be | V20: 0497023380 | AE20: https://app.twizzit.com/public/photos/4421954/s/39c1d6c08bc84b336f4c340a175719810e926066.png | AF20: 1004421954 | AJ20: Zomerstage 2026 U10 & U12 (Oudenaarde) | AK20: Speler
A21: 2182461 | B21: Apostolescu | C21: Vlad Alexandru | D21: nl | E21: M | F21: 06/03/1996 | G21: Nieuwe Brugstraat | H21: 42 | U21: Persoonlijk | V21: 493100390 | AC21: 96.03.06-191.17 | AF21: 1002182461 | AG21: 622980
A22: 2650825 | B22: Arickx | C22: Joao | D22: nl | E22: M | F22: 13/04/2011 | G22: Nestor de Tièrestraat | H22: 124 | V22: 32489669827 | AC22: 11.04.13-143.46 | AF22: 1002650825 | AG22: 730038 | AJ22: J16 B Haantjes CERTIFISC Oudenaarde | AK22: Speler
A23: 2650780 | B23: Baert | C23: Jasper | D23: nl | E23: M | F23: 11/05/2012 | G23: Sneppestraat | H23: 35 | Q23: Vader | R23: baert_stijn@hotmail.com | U23: Moeder | V23: 486584984 | W23: Vader | X23: 473888092 | Y23: Persoonlijk | Z23: 32485376691 | AC23: 12.05.11-117.63 | AE23: https://app.twizzit.com/public/photos/2650780/s/77c3f1ac992ce48307c6c7ab431ab89e2bd37774.png | AF23: 1002650780 | AG23: 736579 | AJ23: J16 B Haantjes CERTIFISC Oudenaarde | AK23: Speler
A24: 6349669 | B24: Balcaen | C24: Christopher | D24: nl | E24: M | F24: 20/04/1995 | U24: Persoonlijk | V24: 0474072810 | AE24: https://app.twizzit.com/public/photos/6349669/s/f1a8e75d54553d15234adcd3add0a63b193557cd.png | AF24: 1006349669 | AG24: 608165
A25: 3472864 | B25: Bauters | C25: Bo | D25: nl | E25: F | F25: 01/09/2017 | G25: Ouwerkerkstraat | H25: 6 | Q25: Vader | R25: Jurgenbauters@gmail.com | V25: 0497533520 | AC25: 17.09.01-092.36 | AE25: https://app.twizzit.com/public/photos/3472864/s/02d5da48533f12868f14fb4b62a0634d769bf8a7.png | AF25: 1003472864 | AJ25: M10 HAANTJES CERTIFISC OUDENAARDE | AK25: Speler
A26: 2182476 | B26: Bauters | C26: Janna | D26: nl | E26: F | F26: 25/01/1994 | G26: Lindestraat | V26: 474344132 | AC26: 94.01.25-262.96 | AE26: https://app.twizzit.com/public/photos/2182476/s/d120dcfc0ec82f0d803829f917b4287681f3dd01.png | AF26: 1002182476 | AG26: 280371 | AJ26: DSE A Haantjes Certifisc Oudenaarde | AK26: Speler
A27: 2182476 | B27: Bauters | C27: Janna | D27: nl | E27: F | F27: 25/01/1994 | G27: Lindestraat | V27: 474344132 | AC27: 94.01.25-262.96 | AE27: https://app.twizzit.com/public/photos/2182476/s/d120dcfc0ec82f0d803829f917b4287681f3dd01.png | AF27: 1002182476 | AG27: 280371 | AJ27: M14 A Haantjes CERTIFISC Oudenaarde | AK27: Coach
A28: 11846410 | B28: Bauters | C28: Noa | D28: nl | E28: F | F28: 10/02/2015 | G28: Ouwerkerkstraat | H28: 6 | Q28: Vader | R28: Jurgenbauters@gmail.com | V28: 0497533520 | AC28: 15.02.10-126.29 | AE28: https://app.twizzit.com/public/photos/11846410/s/0498863fb0a62c783eced92596a817e3339dca11.jpeg | AF28: 1011846410 | AJ28: M12 A HAANTJES CERTIFISC OUDENAARDE | AK28: Speler
A29: 3498747 | B29: Bauters | C29: Rémi | D29: nl | E29: M | F29: 22/12/2008 | G29: Pontstraat | H29: 107 | U29: Moeder | V29: 0497078444 | AF29: 1003498747 | AJ29: J21 A HAANTJES CERTIFISC OUDENAARDE | AK29: Speler
A30: 3498747 | B30: Bauters | C30: Rémi | D30: nl | E30: M | F30: 22/12/2008 | G30: Pontstraat | H30: 107 | U30: Moeder | V30: 0497078444 | AF30: 1003498747 | AJ30: HSE B Haantjes Certifisc Oudenaarde | AK30: Speler
A31: 2182481 | B31: Bauwens | C31: Karine | D31: nl | E31: F | F31: 16/01/1974 | G31: Eekhoutstraat | H31: 13 | AF31: 1002182481
A32: 7329719 | B32: Beeckman | C32: Joppe | D32: nl | E32: M | F32: 26/03/2019 | G32: Vlinderstaat | H32: 10 | R32: ppoitiez@hotmail.com | V32: 0486440775 | AE32: https://app.twizzit.com/public/photos/7329719/s/3900de37cfdf557a3c2ce4dcb1b36ecfefd6df85.png | AF32: 1007329719 | AJ32: G08 Geel HAANTJES CERTIFISC OUDENAARDE | AK32: Speler
A33: 2182486 | B33: Beeckman | C33: Sara | D33: nl | E33: F | F33: 27/11/1981 | G33: Vlinderstraat | H33: 10 | AC33: 81.11.27-094.01 | AE33: https://app.twizzit.com/public/photos/2182486/s/756b8f4f4a0d0890e89db01537d432ba96a97666.png | AF33: 1002182486 | AG33: 721373
A34: 2182491 | B34: Beeckman | C34: Torre | D34: nl | E34: M | F34: 11/08/2011 | G34: Vlinderstaat | H34: 10 | V34: 486440775 | AC34: 11.08.11-227.50 | AE34: https://app.twizzit.com/public/photos/2182491/s/9cf26edd91096e59f19c665e2f0a4528adc17aa7.png | AF34: 1002182491 | AG34: 720212 | AJ34: J16 A Haantjes CERTIFISC Oudenaarde | AK34: Speler | AL34: Clubrefs (Clubref)
A35: 2182491 | B35: Beeckman | C35: Torre | D35: nl | E35: M | F35: 11/08/2011 | G35: Vlinderstaat | H35: 10 | V35: 486440775 | AC35: 11.08.11-227.50 | AE35: https://app.twizzit.com/public/photos/2182491/s/9cf26edd91096e59f19c665e2f0a4528adc17aa7.png | AF35: 1002182491 | AG35: 720212 | AL35: Clubrefs (Clubref)
A36: 3239983 | B36: Beirnaert | C36: Philippe | D36: nl | E36: M | G36: Galgestraat | H36: 86 | V36: 0497271228 | AC36: 63.07.11-337.26 | AF36: 1003239983 | AG36: 7328
A37: 2182501 | B37: Beke | C37: Vince | D37: nl | E37: M | F37: 01/10/2010 | G37: Opperije | H37: 95 | R37: wim.beke@telenet.be | V37: 0494534565 | AC37: 10.10.01-263.16 | AD37: 6 | AE37: https://app.twizzit.com/public/photos/2182501/s/ff9efabb61fd27d35070a050abd98c15c9bfe6c5.png | AF37: 1002182501 | AG37: 715506 | AJ37: J18 B Haantjes CERTIFISC Oudenaarde | AK37: Speler | AL37: Clubrefs (Clubref)
A38: 2182501 | B38: Beke | C38: Vince | D38: nl | E38: M | F38: 01/10/2010 | G38: Opperije | H38: 95 | R38: wim.beke@telenet.be | V38: 0494534565 | AC38: 10.10.01-263.16 | AD38: 6 | AE38: https://app.twizzit.com/public/photos/2182501/s/ff9efabb61fd27d35070a050abd98c15c9bfe6c5.png | AF38: 1002182501 | AG38: 715506 | AJ38: Zomerstage 2026 (Blankenberge) | AK38: Speler
A39: 2713992 | B39: Belien | C39: Elke | D39: nl | E39: F | F39: 06/11/1981 | G39: Koninging Elisabethlaan | H39: 18 | Q39: Partner | R39: dries.goossens@gmail.com | S39: Zoon | T39: slimmerik.briek@gmail.com | U39: Persoonlijk | V39: 320497948892 | W39: Partner | X39: 320478766076 | Y39: Zoon | Z39: 320495362023 | AB39: BE22979596098347 | AC39: 81.11.06-136.07 | AF39: 1002713992 | AG39: 742180 | AL39: Clubrefs (Clubref)
A40: 4080393 | B40: Benoot | C40: Quinten | D40: nl | E40: M | F40: 18/10/2010 | G40: Gentpoortstraat | H40: 66 | I40: 10 | Q40: Vader | R40: Benoothans20@gmail.com | S40: Zoon | T40: Quintenmaetha@gmail.com | U40: Zoon | V40: 0485287357 | W40: Vader | X40: 0472031844 | Y40: Persoonlijk | Z40: 0476900206 | AA40: 32485287357 | AD40: 15 | AE40: https://app.twizzit.com/public/photos/4080393/s/fc77b80b0f519cf2bcaae55fec7f11c92e5c4d9f.jpeg | AF40: 1004080393 | AG40: 753437 | AJ40: J18 B Haantjes CERTIFISC Oudenaarde | AK40: Speler | AL40: Clubrefs (Clubref)
...

Sheet Speler-Coach
A1: Naam | B1: Email | C1: Mobiel | D1: Profielfoto | E1: Lidnummer | F1: 2026-2027 | G1: Functie
A2: {=_xlfn._xlws.FILTER(J2:P743,(P2:P743="Speler")+(P2:P743="Coach"))} -> Lily Adam | B2: Koenadam78@gmail.com | C2: 0476837352 | D2: https://app.twizzit.com/public/photos/2182441/s/eec7946e1a9e80461f26752840c4aedc7d235bab.jpeg | E2: 728412 | F2: DSE A Haantjes Certifisc Oudenaarde | G2: Speler | J2: =Worksheet!C2&" "&Worksheet!B2 -> Koen Adam | K2: =IF(Worksheet!P2<>"",Worksheet!P2,IF(Worksheet!R2<>"",Worksheet!R2,IF(Worksheet!T2<>"",Worksheet!T2,""))) -> koenadam78@gmail.com | L2: =IF(AND(Worksheet!V2<>"",Worksheet!V2<>0),Worksheet!V2&"",IF(AND(Worksheet!X2<>"",Worksheet!X2<>0),Worksheet!X2&"",IF(AND(Worksheet!Z2<>"",Worksheet!Z2<>0),Worksheet!Z2&"",""))) | M2: =IF(Worksheet!AE2="","",Worksheet!AE2) | N2: =IF(Worksheet!AG2="","",Worksheet!AG2) | O2: =IF(Worksheet!AJ2="","",Worksheet!AJ2) | P2: =IF(Worksheet!AK2="","",Worksheet!AK2)
A3: Lily Adam | B3: Koenadam78@gmail.com | C3: 0476837352 | D3: https://app.twizzit.com/public/photos/2182441/s/eec7946e1a9e80461f26752840c4aedc7d235bab.jpeg | E3: 728412 | F3: Zomerstage 2026 (Blankenberge) | G3: Speler | J3: =Worksheet!C3&" "&Worksheet!B3 -> Lily Adam | K3: =IF(Worksheet!P3<>"",Worksheet!P3,IF(Worksheet!R3<>"",Worksheet!R3,IF(Worksheet!T3<>"",Worksheet!T3,""))) -> Koenadam78@gmail.com | L3: =IF(AND(Worksheet!V3<>"",Worksheet!V3<>0),Worksheet!V3&"",IF(AND(Worksheet!X3<>"",Worksheet!X3<>0),Worksheet!X3&"",IF(AND(Worksheet!Z3<>"",Worksheet!Z3<>0),Worksheet!Z3&"",""))) -> 0476837352 | M3: =IF(Worksheet!AE3="","",Worksheet!AE3) -> https://app.twizzit.com/public/photos/2182441/s/eec7946e1a9e80461f26752840c4aedc7d235bab.jpeg | N3: =IF(Worksheet!AG3="","",Worksheet!AG3) -> 728412 | O3: =IF(Worksheet!AJ3="","",Worksheet!AJ3) -> DSE A Haantjes Certifisc Oudenaarde | P3: =IF(Worksheet!AK3="","",Worksheet!AK3) -> Speler
A4: Lily Adam | B4: Koenadam78@gmail.com | C4: 0476837352 | D4: https://app.twizzit.com/public/photos/2182441/s/eec7946e1a9e80461f26752840c4aedc7d235bab.jpeg | E4: 728412 | F4: Trainerspoule | G4: Coach | J4: =Worksheet!C4&" "&Worksheet!B4 -> Lily Adam | K4: =IF(Worksheet!P4<>"",Worksheet!P4,IF(Worksheet!R4<>"",Worksheet!R4,IF(Worksheet!T4<>"",Worksheet!T4,""))) -> Koenadam78@gmail.com | L4: =IF(AND(Worksheet!V4<>"",Worksheet!V4<>0),Worksheet!V4&"",IF(AND(Worksheet!X4<>"",Worksheet!X4<>0),Worksheet!X4&"",IF(AND(Worksheet!Z4<>"",Worksheet!Z4<>0),Worksheet!Z4&"",""))) -> 0476837352 | M4: =IF(Worksheet!AE4="","",Worksheet!AE4) -> https://app.twizzit.com/public/photos/2182441/s/eec7946e1a9e80461f26752840c4aedc7d235bab.jpeg | N4: =IF(Worksheet!AG4="","",Worksheet!AG4) -> 728412 | O4: =IF(Worksheet!AJ4="","",Worksheet!AJ4) -> Zomerstage 2026 (Blankenberge) | P4: =IF(Worksheet!AK4="","",Worksheet!AK4) -> Speler
A5: Kledion Alia | C5: 32499284650 | D5: https://app.twizzit.com/public/photos/2650601/s/f885f644ea63bcfe0579c08cf537df8dcbb43ecc.png | E5: 742334 | F5: G14 A Haantjes CERTIFISC Oudenaarde | G5: Speler | J5: =Worksheet!C5&" "&Worksheet!B5 -> Lily Adam | K5: =IF(Worksheet!P5<>"",Worksheet!P5,IF(Worksheet!R5<>"",Worksheet!R5,IF(Worksheet!T5<>"",Worksheet!T5,""))) -> Koenadam78@gmail.com | L5: =IF(AND(Worksheet!V5<>"",Worksheet!V5<>0),Worksheet!V5&"",IF(AND(Worksheet!X5<>"",Worksheet!X5<>0),Worksheet!X5&"",IF(AND(Worksheet!Z5<>"",Worksheet!Z5<>0),Worksheet!Z5&"",""))) -> 0476837352 | M5: =IF(Worksheet!AE5="","",Worksheet!AE5) -> https://app.twizzit.com/public/photos/2182441/s/eec7946e1a9e80461f26752840c4aedc7d235bab.jpeg | N5: =IF(Worksheet!AG5="","",Worksheet!AG5) -> 728412 | O5: =IF(Worksheet!AJ5="","",Worksheet!AJ5) -> Trainerspoule | P5: =IF(Worksheet!AK5="","",Worksheet!AK5) -> Coach
A6: Kors Altruy | B6: David.altruy@outlook.be | C6: 0479873979 | F6: G14 B Haantjes CERTIFISC Oudenaarde | G6: Speler | J6: =Worksheet!C6&" "&Worksheet!B6 -> Enida Alia | K6: =IF(Worksheet!P6<>"",Worksheet!P6,IF(Worksheet!R6<>"",Worksheet!R6,IF(Worksheet!T6<>"",Worksheet!T6,""))) -> elidona.eni@gmail.com | L6: =IF(AND(Worksheet!V6<>"",Worksheet!V6<>0),Worksheet!V6&"",IF(AND(Worksheet!X6<>"",Worksheet!X6<>0),Worksheet!X6&"",IF(AND(Worksheet!Z6<>"",Worksheet!Z6<>0),Worksheet!Z6&"",""))) -> 00499284650 | M6: =IF(Worksheet!AE6="","",Worksheet!AE6) | N6: =IF(Worksheet!AG6="","",Worksheet!AG6) | O6: =IF(Worksheet!AJ6="","",Worksheet!AJ6) | P6: =IF(Worksheet!AK6="","",Worksheet!AK6)
A7: Lenn Altruy | B7: David.altruy@outlook.be | C7: 0479873979 | F7: Zomerstage 2026 U10 & U12 (Oudenaarde) | G7: Speler | J7: =Worksheet!C7&" "&Worksheet!B7 -> Kledion Alia | K7: =IF(Worksheet!P7<>"",Worksheet!P7,IF(Worksheet!R7<>"",Worksheet!R7,IF(Worksheet!T7<>"",Worksheet!T7,""))) | L7: =IF(AND(Worksheet!V7<>"",Worksheet!V7<>0),Worksheet!V7&"",IF(AND(Worksheet!X7<>"",Worksheet!X7<>0),Worksheet!X7&"",IF(AND(Worksheet!Z7<>"",Worksheet!Z7<>0),Worksheet!Z7&"",""))) -> 32499284650 | M7: =IF(Worksheet!AE7="","",Worksheet!AE7) -> https://app.twizzit.com/public/photos/2650601/s/f885f644ea63bcfe0579c08cf537df8dcbb43ecc.png | N7: =IF(Worksheet!AG7="","",Worksheet!AG7) -> 742334 | O7: =IF(Worksheet!AJ7="","",Worksheet!AJ7) -> G14 A Haantjes CERTIFISC Oudenaarde | P7: =IF(Worksheet!AK7="","",Worksheet!AK7) -> Speler
A8: Lenn Altruy | B8: David.altruy@outlook.be | C8: 0479873979 | F8: G10 Geel HAANTJES CERTIFISC OUDENAARDE | G8: Speler | J8: =Worksheet!C8&" "&Worksheet!B8 -> Kors Altruy | K8: =IF(Worksheet!P8<>"",Worksheet!P8,IF(Worksheet!R8<>"",Worksheet!R8,IF(Worksheet!T8<>"",Worksheet!T8,""))) -> David.altruy@outlook.be | L8: =IF(AND(Worksheet!V8<>"",Worksheet!V8<>0),Worksheet!V8&"",IF(AND(Worksheet!X8<>"",Worksheet!X8<>0),Worksheet!X8&"",IF(AND(Worksheet!Z8<>"",Worksheet!Z8<>0),Worksheet!Z8&"",""))) -> 0479873979 | M8: =IF(Worksheet!AE8="","",Worksheet!AE8) | N8: =IF(Worksheet!AG8="","",Worksheet!AG8) | O8: =IF(Worksheet!AJ8="","",Worksheet!AJ8) -> G14 B Haantjes CERTIFISC Oudenaarde | P8: =IF(Worksheet!AK8="","",Worksheet!AK8) -> Speler
A9: Isa Ameloot-Vanhove | B9: sofie.ameloot@huurland.be | C9: 0483203613 | D9: https://app.twizzit.com/public/photos/5115343/s/0e6908415a8d44c9a80019c8bc87b39596577cc5.jpeg | F9: M16 A Haantjes CERTIFISC Oudenaarde | G9: Speler | J9: =Worksheet!C9&" "&Worksheet!B9 -> Lenn Altruy | K9: =IF(Worksheet!P9<>"",Worksheet!P9,IF(Worksheet!R9<>"",Worksheet!R9,IF(Worksheet!T9<>"",Worksheet!T9,""))) -> David.altruy@outlook.be | L9: =IF(AND(Worksheet!V9<>"",Worksheet!V9<>0),Worksheet!V9&"",IF(AND(Worksheet!X9<>"",Worksheet!X9<>0),Worksheet!X9&"",IF(AND(Worksheet!Z9<>"",Worksheet!Z9<>0),Worksheet!Z9&"",""))) -> 0479873979 | M9: =IF(Worksheet!AE9="","",Worksheet!AE9) | N9: =IF(Worksheet!AG9="","",Worksheet!AG9) | O9: =IF(Worksheet!AJ9="","",Worksheet!AJ9) -> Zomerstage 2026 U10 & U12 (Oudenaarde) | P9: =IF(Worksheet!AK9="","",Worksheet!AK9) -> Speler
A10: Arsen Anar | D10: https://app.twizzit.com/public/photos/11272034/s/339c8f61eeb207a0a7ef82edab3f88fc90d76b77.jpeg | F10: G12 Blauw HAANTJES CERTIFISC OUDENAARDE | G10: Speler | J10: =Worksheet!C10&" "&Worksheet!B10 -> Lenn Altruy | K10: =IF(Worksheet!P10<>"",Worksheet!P10,IF(Worksheet!R10<>"",Worksheet!R10,IF(Worksheet!T10<>"",Worksheet!T10,""))) -> David.altruy@outlook.be | L10: =IF(AND(Worksheet!V10<>"",Worksheet!V10<>0),Worksheet!V10&"",IF(AND(Worksheet!X10<>"",Worksheet!X10<>0),Worksheet!X10&"",IF(AND(Worksheet!Z10<>"",Worksheet!Z10<>0),Worksheet!Z10&"",""))) -> 0479873979 | M10: =IF(Worksheet!AE10="","",Worksheet!AE10) | N10: =IF(Worksheet!AG10="","",Worksheet!AG10) | O10: =IF(Worksheet!AJ10="","",Worksheet!AJ10) -> G10 Geel HAANTJES CERTIFISC OUDENAARDE | P10: =IF(Worksheet!AK10="","",Worksheet!AK10) -> Speler
A11: Mark Anar | D11: https://app.twizzit.com/public/photos/11272030/s/d97169c55e4278dd5f5452138091d993430ca8ab.jpeg | F11: G12 Blauw HAANTJES CERTIFISC OUDENAARDE | G11: Speler | J11: =Worksheet!C11&" "&Worksheet!B11 -> Isa Ameloot-Vanhove | K11: =IF(Worksheet!P11<>"",Worksheet!P11,IF(Worksheet!R11<>"",Worksheet!R11,IF(Worksheet!T11<>"",Worksheet!T11,""))) -> sofie.ameloot@huurland.be | L11: =IF(AND(Worksheet!V11<>"",Worksheet!V11<>0),Worksheet!V11&"",IF(AND(Worksheet!X11<>"",Worksheet!X11<>0),Worksheet!X11&"",IF(AND(Worksheet!Z11<>"",Worksheet!Z11<>0),Worksheet!Z11&"",""))) -> 0483203613 | M11: =IF(Worksheet!AE11="","",Worksheet!AE11) -> https://app.twizzit.com/public/photos/5115343/s/0e6908415a8d44c9a80019c8bc87b39596577cc5.jpeg | N11: =IF(Worksheet!AG11="","",Worksheet!AG11) | O11: =IF(Worksheet!AJ11="","",Worksheet!AJ11) -> M16 A Haantjes CERTIFISC Oudenaarde | P11: =IF(Worksheet!AK11="","",Worksheet!AK11) -> Speler
A12: Marsel Anar | D12: https://app.twizzit.com/public/photos/11272039/s/667db68e153309a064042452d0f619e8acb011fa.jpeg | F12: G12 Blauw HAANTJES CERTIFISC OUDENAARDE | G12: Speler | J12: =Worksheet!C12&" "&Worksheet!B12 -> Arsen Anar | K12: =IF(Worksheet!P12<>"",Worksheet!P12,IF(Worksheet!R12<>"",Worksheet!R12,IF(Worksheet!T12<>"",Worksheet!T12,""))) | L12: =IF(AND(Worksheet!V12<>"",Worksheet!V12<>0),Worksheet!V12&"",IF(AND(Worksheet!X12<>"",Worksheet!X12<>0),Worksheet!X12&"",IF(AND(Worksheet!Z12<>"",Worksheet!Z12<>0),Worksheet!Z12&"",""))) | M12: =IF(Worksheet!AE12="","",Worksheet!AE12) -> https://app.twizzit.com/public/photos/11272034/s/339c8f61eeb207a0a7ef82edab3f88fc90d76b77.jpeg | N12: =IF(Worksheet!AG12="","",Worksheet!AG12) | O12: =IF(Worksheet!AJ12="","",Worksheet!AJ12) -> G12 Blauw HAANTJES CERTIFISC OUDENAARDE | P12: =IF(Worksheet!AK12="","",Worksheet!AK12) -> Speler
A13: Bent Anseeuw | B13: bent.anseeuw@gmail.com | C13: 0497023380 | D13: https://app.twizzit.com/public/photos/2182451/s/d40702514c4affc118f06eee4555b1ca966c4e65.png | E13: 713666 | F13: J18 B Haantjes CERTIFISC Oudenaarde | G13: Speler | J13: =Worksheet!C13&" "&Worksheet!B13 -> Mark Anar | K13: =IF(Worksheet!P13<>"",Worksheet!P13,IF(Worksheet!R13<>"",Worksheet!R13,IF(Worksheet!T13<>"",Worksheet!T13,""))) | L13: =IF(AND(Worksheet!V13<>"",Worksheet!V13<>0),Worksheet!V13&"",IF(AND(Worksheet!X13<>"",Worksheet!X13<>0),Worksheet!X13&"",IF(AND(Worksheet!Z13<>"",Worksheet!Z13<>0),Worksheet!Z13&"",""))) | M13: =IF(Worksheet!AE13="","",Worksheet!AE13) -> https://app.twizzit.com/public/photos/11272030/s/d97169c55e4278dd5f5452138091d993430ca8ab.jpeg | N13: =IF(Worksheet!AG13="","",Worksheet!AG13) | O13: =IF(Worksheet!AJ13="","",Worksheet!AJ13) -> G12 Blauw HAANTJES CERTIFISC OUDENAARDE | P13: =IF(Worksheet!AK13="","",Worksheet!AK13) -> Speler
A14: Bent Anseeuw | B14: bent.anseeuw@gmail.com | C14: 0497023380 | D14: https://app.twizzit.com/public/photos/2182451/s/d40702514c4affc118f06eee4555b1ca966c4e65.png | E14: 713666 | F14: Zomerstage 2026 (Blankenberge) | G14: Speler | J14: =Worksheet!C14&" "&Worksheet!B14 -> Marsel Anar | K14: =IF(Worksheet!P14<>"",Worksheet!P14,IF(Worksheet!R14<>"",Worksheet!R14,IF(Worksheet!T14<>"",Worksheet!T14,""))) | L14: =IF(AND(Worksheet!V14<>"",Worksheet!V14<>0),Worksheet!V14&"",IF(AND(Worksheet!X14<>"",Worksheet!X14<>0),Worksheet!X14&"",IF(AND(Worksheet!Z14<>"",Worksheet!Z14<>0),Worksheet!Z14&"",""))) | M14: =IF(Worksheet!AE14="","",Worksheet!AE14) -> https://app.twizzit.com/public/photos/11272039/s/667db68e153309a064042452d0f619e8acb011fa.jpeg | N14: =IF(Worksheet!AG14="","",Worksheet!AG14) | O14: =IF(Worksheet!AJ14="","",Worksheet!AJ14) -> G12 Blauw HAANTJES CERTIFISC OUDENAARDE | P14: =IF(Worksheet!AK14="","",Worksheet!AK14) -> Speler
A15: Mare Anseeuw | B15: matthias.anseeuw@telenet.be | C15: 497023380 | D15: https://app.twizzit.com/public/photos/2182456/s/112b54676bd1e925e699cce3ec7a25a94902a3a2.png | E15: 735071 | F15: Zomerstage 2026 (Blankenberge) | G15: Speler | J15: =Worksheet!C15&" "&Worksheet!B15 -> Bent Anseeuw | K15: =IF(Worksheet!P15<>"",Worksheet!P15,IF(Worksheet!R15<>"",Worksheet!R15,IF(Worksheet!T15<>"",Worksheet!T15,""))) -> bent.anseeuw@gmail.com | L15: =IF(AND(Worksheet!V15<>"",Worksheet!V15<>0),Worksheet!V15&"",IF(AND(Worksheet!X15<>"",Worksheet!X15<>0),Worksheet!X15&"",IF(AND(Worksheet!Z15<>"",Worksheet!Z15<>0),Worksheet!Z15&"",""))) -> 0497023380 | M15: =IF(Worksheet!AE15="","",Worksheet!AE15) -> https://app.twizzit.com/public/photos/2182451/s/d40702514c4affc118f06eee4555b1ca966c4e65.png | N15: =IF(Worksheet!AG15="","",Worksheet!AG15) -> 713666 | O15: =IF(Worksheet!AJ15="","",Worksheet!AJ15) -> J18 B Haantjes CERTIFISC Oudenaarde | P15: =IF(Worksheet!AK15="","",Worksheet!AK15) -> Speler
A16: Mare Anseeuw | B16: matthias.anseeuw@telenet.be | C16: 497023380 | D16: https://app.twizzit.com/public/photos/2182456/s/112b54676bd1e925e699cce3ec7a25a94902a3a2.png | E16: 735071 | F16: M14 A Haantjes CERTIFISC Oudenaarde | G16: Speler | J16: =Worksheet!C16&" "&Worksheet!B16 -> Bent Anseeuw | K16: =IF(Worksheet!P16<>"",Worksheet!P16,IF(Worksheet!R16<>"",Worksheet!R16,IF(Worksheet!T16<>"",Worksheet!T16,""))) -> bent.anseeuw@gmail.com | L16: =IF(AND(Worksheet!V16<>"",Worksheet!V16<>0),Worksheet!V16&"",IF(AND(Worksheet!X16<>"",Worksheet!X16<>0),Worksheet!X16&"",IF(AND(Worksheet!Z16<>"",Worksheet!Z16<>0),Worksheet!Z16&"",""))) -> 0497023380 | M16: =IF(Worksheet!AE16="","",Worksheet!AE16) -> https://app.twizzit.com/public/photos/2182451/s/d40702514c4affc118f06eee4555b1ca966c4e65.png | N16: =IF(Worksheet!AG16="","",Worksheet!AG16) -> 713666 | O16: =IF(Worksheet!AJ16="","",Worksheet!AJ16) -> Zomerstage 2026 (Blankenberge) | P16: =IF(Worksheet!AK16="","",Worksheet!AK16) -> Speler
A17: Senn Anseeuw | B17: matthias.anseeuw@telenet.be | C17: 0497023380 | D17: https://app.twizzit.com/public/photos/4421954/s/39c1d6c08bc84b336f4c340a175719810e926066.png | F17: G10 Blauw HAANTJES CERTIFISC OUDENAARDE | G17: Speler | J17: =Worksheet!C17&" "&Worksheet!B17 -> Mare Anseeuw | K17: =IF(Worksheet!P17<>"",Worksheet!P17,IF(Worksheet!R17<>"",Worksheet!R17,IF(Worksheet!T17<>"",Worksheet!T17,""))) -> matthias.anseeuw@telenet.be | L17: =IF(AND(Worksheet!V17<>"",Worksheet!V17<>0),Worksheet!V17&"",IF(AND(Worksheet!X17<>"",Worksheet!X17<>0),Worksheet!X17&"",IF(AND(Worksheet!Z17<>"",Worksheet!Z17<>0),Worksheet!Z17&"",""))) -> 497023380 | M17: =IF(Worksheet!AE17="","",Worksheet!AE17) -> https://app.twizzit.com/public/photos/2182456/s/112b54676bd1e925e699cce3ec7a25a94902a3a2.png | N17: =IF(Worksheet!AG17="","",Worksheet!AG17) -> 735071 | O17: =IF(Worksheet!AJ17="","",Worksheet!AJ17) -> Zomerstage 2026 (Blankenberge) | P17: =IF(Worksheet!AK17="","",Worksheet!AK17) -> Speler
A18: Senn Anseeuw | B18: matthias.anseeuw@telenet.be | C18: 0497023380 | D18: https://app.twizzit.com/public/photos/4421954/s/39c1d6c08bc84b336f4c340a175719810e926066.png | F18: Zomerstage 2026 U10 & U12 (Oudenaarde) | G18: Speler | J18: =Worksheet!C18&" "&Worksheet!B18 -> Mare Anseeuw | K18: =IF(Worksheet!P18<>"",Worksheet!P18,IF(Worksheet!R18<>"",Worksheet!R18,IF(Worksheet!T18<>"",Worksheet!T18,""))) -> matthias.anseeuw@telenet.be | L18: =IF(AND(Worksheet!V18<>"",Worksheet!V18<>0),Worksheet!V18&"",IF(AND(Worksheet!X18<>"",Worksheet!X18<>0),Worksheet!X18&"",IF(AND(Worksheet!Z18<>"",Worksheet!Z18<>0),Worksheet!Z18&"",""))) -> 497023380 | M18: =IF(Worksheet!AE18="","",Worksheet!AE18) -> https://app.twizzit.com/public/photos/2182456/s/112b54676bd1e925e699cce3ec7a25a94902a3a2.png | N18: =IF(Worksheet!AG18="","",Worksheet!AG18) -> 735071 | O18: =IF(Worksheet!AJ18="","",Worksheet!AJ18) -> M14 A Haantjes CERTIFISC Oudenaarde | P18: =IF(Worksheet!AK18="","",Worksheet!AK18) -> Speler
A19: Joao Arickx | C19: 32489669827 | E19: 730038 | F19: J16 B Haantjes CERTIFISC Oudenaarde | G19: Speler | J19: =Worksheet!C19&" "&Worksheet!B19 -> Senn Anseeuw | K19: =IF(Worksheet!P19<>"",Worksheet!P19,IF(Worksheet!R19<>"",Worksheet!R19,IF(Worksheet!T19<>"",Worksheet!T19,""))) -> matthias.anseeuw@telenet.be | L19: =IF(AND(Worksheet!V19<>"",Worksheet!V19<>0),Worksheet!V19&"",IF(AND(Worksheet!X19<>"",Worksheet!X19<>0),Worksheet!X19&"",IF(AND(Worksheet!Z19<>"",Worksheet!Z19<>0),Worksheet!Z19&"",""))) -> 0497023380 | M19: =IF(Worksheet!AE19="","",Worksheet!AE19) -> https://app.twizzit.com/public/photos/4421954/s/39c1d6c08bc84b336f4c340a175719810e926066.png | N19: =IF(Worksheet!AG19="","",Worksheet!AG19) | O19: =IF(Worksheet!AJ19="","",Worksheet!AJ19) -> G10 Blauw HAANTJES CERTIFISC OUDENAARDE | P19: =IF(Worksheet!AK19="","",Worksheet!AK19) -> Speler
A20: Jasper Baert | B20: baert_stijn@hotmail.com | C20: 486584984 | D20: https://app.twizzit.com/public/photos/2650780/s/77c3f1ac992ce48307c6c7ab431ab89e2bd37774.png | E20: 736579 | F20: J16 B Haantjes CERTIFISC Oudenaarde | G20: Speler | J20: =Worksheet!C20&" "&Worksheet!B20 -> Senn Anseeuw | K20: =IF(Worksheet!P20<>"",Worksheet!P20,IF(Worksheet!R20<>"",Worksheet!R20,IF(Worksheet!T20<>"",Worksheet!T20,""))) -> matthias.anseeuw@telenet.be | L20: =IF(AND(Worksheet!V20<>"",Worksheet!V20<>0),Worksheet!V20&"",IF(AND(Worksheet!X20<>"",Worksheet!X20<>0),Worksheet!X20&"",IF(AND(Worksheet!Z20<>"",Worksheet!Z20<>0),Worksheet!Z20&"",""))) -> 0497023380 | M20: =IF(Worksheet!AE20="","",Worksheet!AE20) -> https://app.twizzit.com/public/photos/4421954/s/39c1d6c08bc84b336f4c340a175719810e926066.png | N20: =IF(Worksheet!AG20="","",Worksheet!AG20) | O20: =IF(Worksheet!AJ20="","",Worksheet!AJ20) -> Zomerstage 2026 U10 & U12 (Oudenaarde) | P20: =IF(Worksheet!AK20="","",Worksheet!AK20) -> Speler
A21: Bo Bauters | B21: Jurgenbauters@gmail.com | C21: 0497533520 | D21: https://app.twizzit.com/public/photos/3472864/s/02d5da48533f12868f14fb4b62a0634d769bf8a7.png | F21: M10 HAANTJES CERTIFISC OUDENAARDE | G21: Speler | J21: =Worksheet!C21&" "&Worksheet!B21 -> Vlad Alexandru Apostolescu | K21: =IF(Worksheet!P21<>"",Worksheet!P21,IF(Worksheet!R21<>"",Worksheet!R21,IF(Worksheet!T21<>"",Worksheet!T21,""))) | L21: =IF(AND(Worksheet!V21<>"",Worksheet!V21<>0),Worksheet!V21&"",IF(AND(Worksheet!X21<>"",Worksheet!X21<>0),Worksheet!X21&"",IF(AND(Worksheet!Z21<>"",Worksheet!Z21<>0),Worksheet!Z21&"",""))) -> 493100390 | M21: =IF(Worksheet!AE21="","",Worksheet!AE21) | N21: =IF(Worksheet!AG21="","",Worksheet!AG21) -> 622980 | O21: =IF(Worksheet!AJ21="","",Worksheet!AJ21) | P21: =IF(Worksheet!AK21="","",Worksheet!AK21)
A22: Janna Bauters | C22: 474344132 | D22: https://app.twizzit.com/public/photos/2182476/s/d120dcfc0ec82f0d803829f917b4287681f3dd01.png | E22: 280371 | F22: DSE A Haantjes Certifisc Oudenaarde | G22: Speler | J22: =Worksheet!C22&" "&Worksheet!B22 -> Joao Arickx | K22: =IF(Worksheet!P22<>"",Worksheet!P22,IF(Worksheet!R22<>"",Worksheet!R22,IF(Worksheet!T22<>"",Worksheet!T22,""))) | L22: =IF(AND(Worksheet!V22<>"",Worksheet!V22<>0),Worksheet!V22&"",IF(AND(Worksheet!X22<>"",Worksheet!X22<>0),Worksheet!X22&"",IF(AND(Worksheet!Z22<>"",Worksheet!Z22<>0),Worksheet!Z22&"",""))) -> 32489669827 | M22: =IF(Worksheet!AE22="","",Worksheet!AE22) | N22: =IF(Worksheet!AG22="","",Worksheet!AG22) -> 730038 | O22: =IF(Worksheet!AJ22="","",Worksheet!AJ22) -> J16 B Haantjes CERTIFISC Oudenaarde | P22: =IF(Worksheet!AK22="","",Worksheet!AK22) -> Speler
A23: Janna Bauters | C23: 474344132 | D23: https://app.twizzit.com/public/photos/2182476/s/d120dcfc0ec82f0d803829f917b4287681f3dd01.png | E23: 280371 | F23: M14 A Haantjes CERTIFISC Oudenaarde | G23: Coach | J23: =Worksheet!C23&" "&Worksheet!B23 -> Jasper Baert | K23: =IF(Worksheet!P23<>"",Worksheet!P23,IF(Worksheet!R23<>"",Worksheet!R23,IF(Worksheet!T23<>"",Worksheet!T23,""))) -> baert_stijn@hotmail.com | L23: =IF(AND(Worksheet!V23<>"",Worksheet!V23<>0),Worksheet!V23&"",IF(AND(Worksheet!X23<>"",Worksheet!X23<>0),Worksheet!X23&"",IF(AND(Worksheet!Z23<>"",Worksheet!Z23<>0),Worksheet!Z23&"",""))) -> 486584984 | M23: =IF(Worksheet!AE23="","",Worksheet!AE23) -> https://app.twizzit.com/public/photos/2650780/s/77c3f1ac992ce48307c6c7ab431ab89e2bd37774.png | N23: =IF(Worksheet!AG23="","",Worksheet!AG23) -> 736579 | O23: =IF(Worksheet!AJ23="","",Worksheet!AJ23) -> J16 B Haantjes CERTIFISC Oudenaarde | P23: =IF(Worksheet!AK23="","",Worksheet!AK23) -> Speler
A24: Noa Bauters | B24: Jurgenbauters@gmail.com | C24: 0497533520 | D24: https://app.twizzit.com/public/photos/11846410/s/0498863fb0a62c783eced92596a817e3339dca11.jpeg | F24: M12 A HAANTJES CERTIFISC OUDENAARDE | G24: Speler | J24: =Worksheet!C24&" "&Worksheet!B24 -> Christopher Balcaen | K24: =IF(Worksheet!P24<>"",Worksheet!P24,IF(Worksheet!R24<>"",Worksheet!R24,IF(Worksheet!T24<>"",Worksheet!T24,""))) | L24: =IF(AND(Worksheet!V24<>"",Worksheet!V24<>0),Worksheet!V24&"",IF(AND(Worksheet!X24<>"",Worksheet!X24<>0),Worksheet!X24&"",IF(AND(Worksheet!Z24<>"",Worksheet!Z24<>0),Worksheet!Z24&"",""))) -> 0474072810 | M24: =IF(Worksheet!AE24="","",Worksheet!AE24) -> https://app.twizzit.com/public/photos/6349669/s/f1a8e75d54553d15234adcd3add0a63b193557cd.png | N24: =IF(Worksheet!AG24="","",Worksheet!AG24) -> 608165 | O24: =IF(Worksheet!AJ24="","",Worksheet!AJ24) | P24: =IF(Worksheet!AK24="","",Worksheet!AK24)
A25: Rémi Bauters | C25: 0497078444 | F25: J21 A HAANTJES CERTIFISC OUDENAARDE | G25: Speler | J25: =Worksheet!C25&" "&Worksheet!B25 -> Bo Bauters | K25: =IF(Worksheet!P25<>"",Worksheet!P25,IF(Worksheet!R25<>"",Worksheet!R25,IF(Worksheet!T25<>"",Worksheet!T25,""))) -> Jurgenbauters@gmail.com | L25: =IF(AND(Worksheet!V25<>"",Worksheet!V25<>0),Worksheet!V25&"",IF(AND(Worksheet!X25<>"",Worksheet!X25<>0),Worksheet!X25&"",IF(AND(Worksheet!Z25<>"",Worksheet!Z25<>0),Worksheet!Z25&"",""))) -> 0497533520 | M25: =IF(Worksheet!AE25="","",Worksheet!AE25) -> https://app.twizzit.com/public/photos/3472864/s/02d5da48533f12868f14fb4b62a0634d769bf8a7.png | N25: =IF(Worksheet!AG25="","",Worksheet!AG25) | O25: =IF(Worksheet!AJ25="","",Worksheet!AJ25) -> M10 HAANTJES CERTIFISC OUDENAARDE | P25: =IF(Worksheet!AK25="","",Worksheet!AK25) -> Speler
A26: Rémi Bauters | C26: 0497078444 | F26: HSE B Haantjes Certifisc Oudenaarde | G26: Speler | J26: =Worksheet!C26&" "&Worksheet!B26 -> Janna Bauters | K26: =IF(Worksheet!P26<>"",Worksheet!P26,IF(Worksheet!R26<>"",Worksheet!R26,IF(Worksheet!T26<>"",Worksheet!T26,""))) | L26: =IF(AND(Worksheet!V26<>"",Worksheet!V26<>0),Worksheet!V26&"",IF(AND(Worksheet!X26<>"",Worksheet!X26<>0),Worksheet!X26&"",IF(AND(Worksheet!Z26<>"",Worksheet!Z26<>0),Worksheet!Z26&"",""))) -> 474344132 | M26: =IF(Worksheet!AE26="","",Worksheet!AE26) -> https://app.twizzit.com/public/photos/2182476/s/d120dcfc0ec82f0d803829f917b4287681f3dd01.png | N26: =IF(Worksheet!AG26="","",Worksheet!AG26) -> 280371 | O26: =IF(Worksheet!AJ26="","",Worksheet!AJ26) -> DSE A Haantjes Certifisc Oudenaarde | P26: =IF(Worksheet!AK26="","",Worksheet!AK26) -> Speler
A27: Joppe Beeckman | B27: ppoitiez@hotmail.com | C27: 0486440775 | D27: https://app.twizzit.com/public/photos/7329719/s/3900de37cfdf557a3c2ce4dcb1b36ecfefd6df85.png | F27: G08 Geel HAANTJES CERTIFISC OUDENAARDE | G27: Speler | J27: =Worksheet!C27&" "&Worksheet!B27 -> Janna Bauters | K27: =IF(Worksheet!P27<>"",Worksheet!P27,IF(Worksheet!R27<>"",Worksheet!R27,IF(Worksheet!T27<>"",Worksheet!T27,""))) | L27: =IF(AND(Worksheet!V27<>"",Worksheet!V27<>0),Worksheet!V27&"",IF(AND(Worksheet!X27<>"",Worksheet!X27<>0),Worksheet!X27&"",IF(AND(Worksheet!Z27<>"",Worksheet!Z27<>0),Worksheet!Z27&"",""))) -> 474344132 | M27: =IF(Worksheet!AE27="","",Worksheet!AE27) -> https://app.twizzit.com/public/photos/2182476/s/d120dcfc0ec82f0d803829f917b4287681f3dd01.png | N27: =IF(Worksheet!AG27="","",Worksheet!AG27) -> 280371 | O27: =IF(Worksheet!AJ27="","",Worksheet!AJ27) -> M14 A Haantjes CERTIFISC Oudenaarde | P27: =IF(Worksheet!AK27="","",Worksheet!AK27) -> Coach
A28: Torre Beeckman | C28: 486440775 | D28: https://app.twizzit.com/public/photos/2182491/s/9cf26edd91096e59f19c665e2f0a4528adc17aa7.png | E28: 720212 | F28: J16 A Haantjes CERTIFISC Oudenaarde | G28: Speler | J28: =Worksheet!C28&" "&Worksheet!B28 -> Noa Bauters | K28: =IF(Worksheet!P28<>"",Worksheet!P28,IF(Worksheet!R28<>"",Worksheet!R28,IF(Worksheet!T28<>"",Worksheet!T28,""))) -> Jurgenbauters@gmail.com | L28: =IF(AND(Worksheet!V28<>"",Worksheet!V28<>0),Worksheet!V28&"",IF(AND(Worksheet!X28<>"",Worksheet!X28<>0),Worksheet!X28&"",IF(AND(Worksheet!Z28<>"",Worksheet!Z28<>0),Worksheet!Z28&"",""))) -> 0497533520 | M28: =IF(Worksheet!AE28="","",Worksheet!AE28) -> https://app.twizzit.com/public/photos/11846410/s/0498863fb0a62c783eced92596a817e3339dca11.jpeg | N28: =IF(Worksheet!AG28="","",Worksheet!AG28) | O28: =IF(Worksheet!AJ28="","",Worksheet!AJ28) -> M12 A HAANTJES CERTIFISC OUDENAARDE | P28: =IF(Worksheet!AK28="","",Worksheet!AK28) -> Speler
A29: Vince Beke | B29: wim.beke@telenet.be | C29: 0494534565 | D29: https://app.twizzit.com/public/photos/2182501/s/ff9efabb61fd27d35070a050abd98c15c9bfe6c5.png | E29: 715506 | F29: J18 B Haantjes CERTIFISC Oudenaarde | G29: Speler | J29: =Worksheet!C29&" "&Worksheet!B29 -> Rémi Bauters | K29: =IF(Worksheet!P29<>"",Worksheet!P29,IF(Worksheet!R29<>"",Worksheet!R29,IF(Worksheet!T29<>"",Worksheet!T29,""))) | L29: =IF(AND(Worksheet!V29<>"",Worksheet!V29<>0),Worksheet!V29&"",IF(AND(Worksheet!X29<>"",Worksheet!X29<>0),Worksheet!X29&"",IF(AND(Worksheet!Z29<>"",Worksheet!Z29<>0),Worksheet!Z29&"",""))) -> 0497078444 | M29: =IF(Worksheet!AE29="","",Worksheet!AE29) | N29: =IF(Worksheet!AG29="","",Worksheet!AG29) | O29: =IF(Worksheet!AJ29="","",Worksheet!AJ29) -> J21 A HAANTJES CERTIFISC OUDENAARDE | P29: =IF(Worksheet!AK29="","",Worksheet!AK29) -> Speler
A30: Vince Beke | B30: wim.beke@telenet.be | C30: 0494534565 | D30: https://app.twizzit.com/public/photos/2182501/s/ff9efabb61fd27d35070a050abd98c15c9bfe6c5.png | E30: 715506 | F30: Zomerstage 2026 (Blankenberge) | G30: Speler | J30: =Worksheet!C30&" "&Worksheet!B30 -> Rémi Bauters | K30: =IF(Worksheet!P30<>"",Worksheet!P30,IF(Worksheet!R30<>"",Worksheet!R30,IF(Worksheet!T30<>"",Worksheet!T30,""))) | L30: =IF(AND(Worksheet!V30<>"",Worksheet!V30<>0),Worksheet!V30&"",IF(AND(Worksheet!X30<>"",Worksheet!X30<>0),Worksheet!X30&"",IF(AND(Worksheet!Z30<>"",Worksheet!Z30<>0),Worksheet!Z30&"",""))) -> 0497078444 | M30: =IF(Worksheet!AE30="","",Worksheet!AE30) | N30: =IF(Worksheet!AG30="","",Worksheet!AG30) | O30: =IF(Worksheet!AJ30="","",Worksheet!AJ30) -> HSE B Haantjes Certifisc Oudenaarde | P30: =IF(Worksheet!AK30="","",Worksheet!AK30) -> Speler
A31: Quinten Benoot | B31: Benoothans20@gmail.com | C31: 0485287357 | D31: https://app.twizzit.com/public/photos/4080393/s/fc77b80b0f519cf2bcaae55fec7f11c92e5c4d9f.jpeg | E31: 753437 | F31: J18 B Haantjes CERTIFISC Oudenaarde | G31: Speler | J31: =Worksheet!C31&" "&Worksheet!B31 -> Karine Bauwens | K31: =IF(Worksheet!P31<>"",Worksheet!P31,IF(Worksheet!R31<>"",Worksheet!R31,IF(Worksheet!T31<>"",Worksheet!T31,""))) | L31: =IF(AND(Worksheet!V31<>"",Worksheet!V31<>0),Worksheet!V31&"",IF(AND(Worksheet!X31<>"",Worksheet!X31<>0),Worksheet!X31&"",IF(AND(Worksheet!Z31<>"",Worksheet!Z31<>0),Worksheet!Z31&"",""))) | M31: =IF(Worksheet!AE31="","",Worksheet!AE31) | N31: =IF(Worksheet!AG31="","",Worksheet!AG31) | O31: =IF(Worksheet!AJ31="","",Worksheet!AJ31) | P31: =IF(Worksheet!AK31="","",Worksheet!AK31)
A32: Emile Berkvens | C32: 474613344 | D32: https://app.twizzit.com/public/photos/2650778/s/15d2f475817dbbc2474d7d1a8b8b6a06ed3f6c72.png | E32: 739383 | F32: J16 B Haantjes CERTIFISC Oudenaarde | G32: Speler | J32: =Worksheet!C32&" "&Worksheet!B32 -> Joppe Beeckman | K32: =IF(Worksheet!P32<>"",Worksheet!P32,IF(Worksheet!R32<>"",Worksheet!R32,IF(Worksheet!T32<>"",Worksheet!T32,""))) -> ppoitiez@hotmail.com | L32: =IF(AND(Worksheet!V32<>"",Worksheet!V32<>0),Worksheet!V32&"",IF(AND(Worksheet!X32<>"",Worksheet!X32<>0),Worksheet!X32&"",IF(AND(Worksheet!Z32<>"",Worksheet!Z32<>0),Worksheet!Z32&"",""))) -> 0486440775 | M32: =IF(Worksheet!AE32="","",Worksheet!AE32) -> https://app.twizzit.com/public/photos/7329719/s/3900de37cfdf557a3c2ce4dcb1b36ecfefd6df85.png | N32: =IF(Worksheet!AG32="","",Worksheet!AG32) | O32: =IF(Worksheet!AJ32="","",Worksheet!AJ32) -> G08 Geel HAANTJES CERTIFISC OUDENAARDE | P32: =IF(Worksheet!AK32="","",Worksheet!AK32) -> Speler
A33: Celeste Blancke | C33: 478385011 | D33: https://app.twizzit.com/public/photos/3500953/s/601083ebf506787be01432d1e891039519c5d9b6.jpeg | E33: 749419 | F33: Zomerstage 2026 (Blankenberge) | G33: Speler | J33: =Worksheet!C33&" "&Worksheet!B33 -> Sara Beeckman | K33: =IF(Worksheet!P33<>"",Worksheet!P33,IF(Worksheet!R33<>"",Worksheet!R33,IF(Worksheet!T33<>"",Worksheet!T33,""))) | L33: =IF(AND(Worksheet!V33<>"",Worksheet!V33<>0),Worksheet!V33&"",IF(AND(Worksheet!X33<>"",Worksheet!X33<>0),Worksheet!X33&"",IF(AND(Worksheet!Z33<>"",Worksheet!Z33<>0),Worksheet!Z33&"",""))) | M33: =IF(Worksheet!AE33="","",Worksheet!AE33) -> https://app.twizzit.com/public/photos/2182486/s/756b8f4f4a0d0890e89db01537d432ba96a97666.png | N33: =IF(Worksheet!AG33="","",Worksheet!AG33) -> 721373 | O33: =IF(Worksheet!AJ33="","",Worksheet!AJ33) | P33: =IF(Worksheet!AK33="","",Worksheet!AK33)
A34: Celeste Blancke | C34: 478385011 | D34: https://app.twizzit.com/public/photos/3500953/s/601083ebf506787be01432d1e891039519c5d9b6.jpeg | E34: 749419 | F34: M14 A Haantjes CERTIFISC Oudenaarde | G34: Speler | J34: =Worksheet!C34&" "&Worksheet!B34 -> Torre Beeckman | K34: =IF(Worksheet!P34<>"",Worksheet!P34,IF(Worksheet!R34<>"",Worksheet!R34,IF(Worksheet!T34<>"",Worksheet!T34,""))) | L34: =IF(AND(Worksheet!V34<>"",Worksheet!V34<>0),Worksheet!V34&"",IF(AND(Worksheet!X34<>"",Worksheet!X34<>0),Worksheet!X34&"",IF(AND(Worksheet!Z34<>"",Worksheet!Z34<>0),Worksheet!Z34&"",""))) -> 486440775 | M34: =IF(Worksheet!AE34="","",Worksheet!AE34) -> https://app.twizzit.com/public/photos/2182491/s/9cf26edd91096e59f19c665e2f0a4528adc17aa7.png | N34: =IF(Worksheet!AG34="","",Worksheet!AG34) -> 720212 | O34: =IF(Worksheet!AJ34="","",Worksheet!AJ34) -> J16 A Haantjes CERTIFISC Oudenaarde | P34: =IF(Worksheet!AK34="","",Worksheet!AK34) -> Speler
A35: Merel Blancke | C35: 0478385011 | D35: https://app.twizzit.com/public/photos/5568565/s/d285ba208d969f77d6c249fb61359c50c614e6ac.png | F35: M16 A Haantjes CERTIFISC Oudenaarde | G35: Speler | J35: =Worksheet!C35&" "&Worksheet!B35 -> Torre Beeckman | K35: =IF(Worksheet!P35<>"",Worksheet!P35,IF(Worksheet!R35<>"",Worksheet!R35,IF(Worksheet!T35<>"",Worksheet!T35,""))) | L35: =IF(AND(Worksheet!V35<>"",Worksheet!V35<>0),Worksheet!V35&"",IF(AND(Worksheet!X35<>"",Worksheet!X35<>0),Worksheet!X35&"",IF(AND(Worksheet!Z35<>"",Worksheet!Z35<>0),Worksheet!Z35&"",""))) -> 486440775 | M35: =IF(Worksheet!AE35="","",Worksheet!AE35) -> https://app.twizzit.com/public/photos/2182491/s/9cf26edd91096e59f19c665e2f0a4528adc17aa7.png | N35: =IF(Worksheet!AG35="","",Worksheet!AG35) -> 720212 | O35: =IF(Worksheet!AJ35="","",Worksheet!AJ35) | P35: =IF(Worksheet!AK35="","",Worksheet!AK35)
A36: Merel Blancke | C36: 0478385011 | D36: https://app.twizzit.com/public/photos/5568565/s/d285ba208d969f77d6c249fb61359c50c614e6ac.png | F36: Zomerstage 2026 (Blankenberge) | G36: Speler | J36: =Worksheet!C36&" "&Worksheet!B36 -> Philippe Beirnaert | K36: =IF(Worksheet!P36<>"",Worksheet!P36,IF(Worksheet!R36<>"",Worksheet!R36,IF(Worksheet!T36<>"",Worksheet!T36,""))) | L36: =IF(AND(Worksheet!V36<>"",Worksheet!V36<>0),Worksheet!V36&"",IF(AND(Worksheet!X36<>"",Worksheet!X36<>0),Worksheet!X36&"",IF(AND(Worksheet!Z36<>"",Worksheet!Z36<>0),Worksheet!Z36&"",""))) -> 0497271228 | M36: =IF(Worksheet!AE36="","",Worksheet!AE36) | N36: =IF(Worksheet!AG36="","",Worksheet!AG36) -> 7328 | O36: =IF(Worksheet!AJ36="","",Worksheet!AJ36) | P36: =IF(Worksheet!AK36="","",Worksheet!AK36)
A37: Vic Blommaert | B37: jeroen.blommaert@gmail.com | C37: 0477059912 | D37: https://app.twizzit.com/public/photos/7328384/s/880c055e18cd3fa9e57719da7306434e04eaf905.png | F37: G10 Geel HAANTJES CERTIFISC OUDENAARDE | G37: Speler | J37: =Worksheet!C37&" "&Worksheet!B37 -> Vince Beke | K37: =IF(Worksheet!P37<>"",Worksheet!P37,IF(Worksheet!R37<>"",Worksheet!R37,IF(Worksheet!T37<>"",Worksheet!T37,""))) -> wim.beke@telenet.be | L37: =IF(AND(Worksheet!V37<>"",Worksheet!V37<>0),Worksheet!V37&"",IF(AND(Worksheet!X37<>"",Worksheet!X37<>0),Worksheet!X37&"",IF(AND(Worksheet!Z37<>"",Worksheet!Z37<>0),Worksheet!Z37&"",""))) -> 0494534565 | M37: =IF(Worksheet!AE37="","",Worksheet!AE37) -> https://app.twizzit.com/public/photos/2182501/s/ff9efabb61fd27d35070a050abd98c15c9bfe6c5.png | N37: =IF(Worksheet!AG37="","",Worksheet!AG37) -> 715506 | O37: =IF(Worksheet!AJ37="","",Worksheet!AJ37) -> J18 B Haantjes CERTIFISC Oudenaarde | P37: =IF(Worksheet!AK37="","",Worksheet!AK37) -> Speler
A38: Matti Bogaert | B38: mboogie800@hotmail.com | C38: 0478427271 | E38: 737616 | F38: J18 A Haantjes CERTIFISC Oudenaarde | G38: Speler | J38: =Worksheet!C38&" "&Worksheet!B38 -> Vince Beke | K38: =IF(Worksheet!P38<>"",Worksheet!P38,IF(Worksheet!R38<>"",Worksheet!R38,IF(Worksheet!T38<>"",Worksheet!T38,""))) -> wim.beke@telenet.be | L38: =IF(AND(Worksheet!V38<>"",Worksheet!V38<>0),Worksheet!V38&"",IF(AND(Worksheet!X38<>"",Worksheet!X38<>0),Worksheet!X38&"",IF(AND(Worksheet!Z38<>"",Worksheet!Z38<>0),Worksheet!Z38&"",""))) -> 0494534565 | M38: =IF(Worksheet!AE38="","",Worksheet!AE38) -> https://app.twizzit.com/public/photos/2182501/s/ff9efabb61fd27d35070a050abd98c15c9bfe6c5.png | N38: =IF(Worksheet!AG38="","",Worksheet!AG38) -> 715506 | O38: =IF(Worksheet!AJ38="","",Worksheet!AJ38) -> Zomerstage 2026 (Blankenberge) | P38: =IF(Worksheet!AK38="","",Worksheet!AK38) -> Speler
A39: Matti Bogaert | B39: mboogie800@hotmail.com | C39: 0478427271 | E39: 737616 | F39: HSE B Haantjes Certifisc Oudenaarde | G39: Speler | J39: =Worksheet!C39&" "&Worksheet!B39 -> Elke Belien | K39: =IF(Worksheet!P39<>"",Worksheet!P39,IF(Worksheet!R39<>"",Worksheet!R39,IF(Worksheet!T39<>"",Worksheet!T39,""))) -> dries.goossens@gmail.com | L39: =IF(AND(Worksheet!V39<>"",Worksheet!V39<>0),Worksheet!V39&"",IF(AND(Worksheet!X39<>"",Worksheet!X39<>0),Worksheet!X39&"",IF(AND(Worksheet!Z39<>"",Worksheet!Z39<>0),Worksheet!Z39&"",""))) -> 320497948892 | M39: =IF(Worksheet!AE39="","",Worksheet!AE39) | N39: =IF(Worksheet!AG39="","",Worksheet!AG39) -> 742180 | O39: =IF(Worksheet!AJ39="","",Worksheet!AJ39) | P39: =IF(Worksheet!AK39="","",Worksheet!AK39)
A40: Maurice Boonaert | B40: reggyboonaert@outlook.be | C40: 0478731137 | F40: G08 Groen HAANTJES CERTIFISC OUDENAARDE | G40: Speler | J40: =Worksheet!C40&" "&Worksheet!B40 -> Quinten Benoot | K40: =IF(Worksheet!P40<>"",Worksheet!P40,IF(Worksheet!R40<>"",Worksheet!R40,IF(Worksheet!T40<>"",Worksheet!T40,""))) -> Benoothans20@gmail.com | L40: =IF(AND(Worksheet!V40<>"",Worksheet!V40<>0),Worksheet!V40&"",IF(AND(Worksheet!X40<>"",Worksheet!X40<>0),Worksheet!X40&"",IF(AND(Worksheet!Z40<>"",Worksheet!Z40<>0),Worksheet!Z40&"",""))) -> 0485287357 | M40: =IF(Worksheet!AE40="","",Worksheet!AE40) -> https://app.twizzit.com/public/photos/4080393/s/fc77b80b0f519cf2bcaae55fec7f11c92e5c4d9f.jpeg | N40: =IF(Worksheet!AG40="","",Worksheet!AG40) -> 753437 | O40: =IF(Worksheet!AJ40="","",Worksheet!AJ40) -> J18 B Haantjes CERTIFISC Oudenaarde | P40: =IF(Worksheet!AK40="","",Worksheet!AK40) -> Speler
...

Sheet Sorted by Team
A1: Naam | B1: Email | C1: Mobiel | D1: Profielfoto | E1: Lidnummer | F1: 2026-2027 | G1: Functie
A2: {=_xlfn._xlws.SORT('Speler-Coach'!A2:G394,6,1)} -> Odet Castelain | B2: evelyn.demesel@hotmail.be | C2: 32495228616 | F2: Balschool U6 | G2: Speler
A3: Cécile De Groote Hoebeke | B3: hoebekehanne@gmail.com | C3: 0473630733 | F3: Balschool U6 | G3: Speler
A4: Mauro De Leersnyder | B4: joke.toye@gmail.com | C4: 0475403946 | F4: Balschool U6 | G4: Speler
A5: Rami Decock | B5: decock.anthony07@gmail.com | C5: 049819525 | F5: Balschool U6 | G5: Speler
A6: Jakob Delbaere | C6: 0474233989 | F6: Balschool U6 | G6: Speler
A7: Cérile Doublet | B7: doubletbenoit@msn.com | C7: 0472578222 | F7: Balschool U6 | G7: Speler
A8: Cas Elyn | B8: lievemoyaert@icloud.com | C8: 0495653737 | F8: Balschool U6 | G8: Speler
A9: Tiaz Molly | B9: Molly.diederick@gmail.com | C9: 0494605068 | F9: Balschool U6 | G9: Speler
A10: Alba Slembrouck | B10: alexandra-kemp@hotmail.com | C10: 00472902002 | F10: Balschool U6 | G10: Speler
A11: Lily Adam | B11: Koenadam78@gmail.com | C11: 0476837352 | D11: https://app.twizzit.com/public/photos/2182441/s/eec7946e1a9e80461f26752840c4aedc7d235bab.jpeg | E11: 728412 | F11: DSE A Haantjes Certifisc Oudenaarde | G11: Speler
A12: Janna Bauters | C12: 474344132 | D12: https://app.twizzit.com/public/photos/2182476/s/d120dcfc0ec82f0d803829f917b4287681f3dd01.png | E12: 280371 | F12: DSE A Haantjes Certifisc Oudenaarde | G12: Speler
A13: Marie Bourdeaud'hui | C13: 32572791 | D13: https://app.twizzit.com/public/photos/2182516/s/0d7291570c9e5cf142cd892c8fd7ace8c517270a.png | E13: 714083 | F13: DSE A Haantjes Certifisc Oudenaarde | G13: Speler
A14: Aishatu Lieve Buadee | C14: 0496745543 | F14: DSE A Haantjes Certifisc Oudenaarde | G14: Speler
A15: Iris Calewaert | E15: 622248 | F15: DSE A Haantjes Certifisc Oudenaarde | G15: Speler
A16: Bart Cattoir | E16: 20854 | F16: DSE A Haantjes Certifisc Oudenaarde | G16: Coach
A17: Alice Cokelaere | B17: sofie.pattyn@telenet.be | C17: 0477681738 | E17: 669074 | F17: DSE A Haantjes Certifisc Oudenaarde | G17: Speler
A18: Karen Dans | C18: 320494698322 | D18: https://app.twizzit.com/public/photos/2182586/s/3c061ecaa7eb60b4e8b27f2490fa3fff24778b0c.png | E18: 220520 | F18: DSE A Haantjes Certifisc Oudenaarde | G18: Speler
A19: Kimberley De Smet | D19: https://app.twizzit.com/public/photos/2182696/s/b3404003062e85e1b45f5fca9b0565fe70029286.png | E19: 266618 | F19: DSE A Haantjes Certifisc Oudenaarde | G19: Speler
A20: Heike Guenter | B20: Heike.guenter@telenet.be | C20: 0474664394 | E20: 727038 | F20: DSE A Haantjes Certifisc Oudenaarde | G20: Speler
A21: Lente Verhaeghe | B21: achiel.en.hector@hotmail.com | D21: https://app.twizzit.com/public/photos/3706826/s/7283d518f82547e0fb530790cddedb0edf0a5785.jpeg | F21: DSE A Haantjes Certifisc Oudenaarde | G21: Speler
A22: Tybe De Clercq | B22: freyadesmet@hotmail.com | C22: 0476214551 | F22: G08 Blauw HAANTJES CERTIFISC OUDENAARDE | G22: Speler
A23: Jef Lauwereins | B23: lauwereins.steven@gmail.com | C23: 0474317844 | F23: G08 Blauw HAANTJES CERTIFISC OUDENAARDE | G23: Speler
A24: Juul Messeeuw | B24: lynnvdwiele@hotmail.com | C24: 0486610793 | F24: G08 Blauw HAANTJES CERTIFISC OUDENAARDE | G24: Speler
A25: Rover Naessens | B25: deesnaessens@hotmail.com | C25: 0495844733 | D25: https://app.twizzit.com/public/photos/7328405/s/a238a3bac0fa83cb173f769b5ce64dd7bdebab6d.jpeg | F25: G08 Blauw HAANTJES CERTIFISC OUDENAARDE | G25: Speler
A26: Théo Parmentier | B26: jensparmentier@gmail.com | C26: 0498076133 | F26: G08 Blauw HAANTJES CERTIFISC OUDENAARDE | G26: Speler
A27: Thibaut Sadaune | B27: bartsadaune@hotmail.com | C27: 32494904656 | D27: https://app.twizzit.com/public/photos/8418475/s/c44854e7fe4ecdd14617bb0fe2e99a30f0cedc15.jpeg | F27: G08 Blauw HAANTJES CERTIFISC OUDENAARDE | G27: Speler
A28: Aster Van Cauwenberghe | C28: 0476529185 | D28: https://app.twizzit.com/public/photos/6080950/s/e37d4499e2422d263ca72ca5adc1adb614aa1f40.jpeg | E28: 768928 | F28: G08 Blauw HAANTJES CERTIFISC OUDENAARDE | G28: Speler
A29: Lander Van De Maele | B29: jensvdmaele@gmail.com | C29: 0479246218 | D29: https://app.twizzit.com/public/photos/10715682/s/9ac40a7d3bcb76b36d9290dcb9c3bcdc167e2add.jpeg | F29: G08 Blauw HAANTJES CERTIFISC OUDENAARDE | G29: Speler
A30: Ronan Vanneste | B30: Koen.vanneste.k@gmail.com | C30: 0476974657 | D30: https://app.twizzit.com/public/photos/7992424/s/7741759047d554aed7aaac84a694a4ea4a62b085.jpeg | F30: G08 Blauw HAANTJES CERTIFISC OUDENAARDE | G30: Speler
A31: Océane Wisbecq | B31: jasper.wisbecq@hotmail.com | C31: 0472459757 | F31: G08 Blauw HAANTJES CERTIFISC OUDENAARDE | G31: Speler
A32: Joppe Beeckman | B32: ppoitiez@hotmail.com | C32: 0486440775 | D32: https://app.twizzit.com/public/photos/7329719/s/3900de37cfdf557a3c2ce4dcb1b36ecfefd6df85.png | F32: G08 Geel HAANTJES CERTIFISC OUDENAARDE | G32: Speler
A33: Leon Boone | B33: dieter.boone@telenet.be | C33: 0496024078 | F33: G08 Geel HAANTJES CERTIFISC OUDENAARDE | G33: Speler
A34: Jonah Cattoir | F34: G08 Geel HAANTJES CERTIFISC OUDENAARDE | G34: Coach
A35: Lasse Cattoir | D35: https://app.twizzit.com/public/photos/9522553/s/70d508b65eaba88af49f20bd545e119d36420c07.png | F35: G08 Geel HAANTJES CERTIFISC OUDENAARDE | G35: Speler
A36: Madelein De Groote Hoebeke | B36: hoebekehanne@gmail.com | C36: 0473630733 | D36: https://app.twizzit.com/public/photos/7992432/s/9093b3c321ebca1981daea541211e5a7f8dcd3e7.png | F36: G08 Geel HAANTJES CERTIFISC OUDENAARDE | G36: Speler
A37: Elli De Zitter | B37: de.zitter.steve@gmail.com | C37: 0473423222 | F37: G08 Geel HAANTJES CERTIFISC OUDENAARDE | G37: Speler
A38: Gust Dupont | B38: sarah.verhellen@hotmail.com | C38: 0470112368 | F38: G08 Geel HAANTJES CERTIFISC OUDENAARDE | G38: Speler
A39: Robin Elyn | B39: lievemoyaert@icloud.com | C39: 0495653737 | F39: G08 Geel HAANTJES CERTIFISC OUDENAARDE | G39: Speler
A40: Oskar Luyten | B40: liesbeth_boudrez@hotmail.be | C40: 32499650150 | D40: https://app.twizzit.com/public/photos/6067218/s/05d3b6d34153ded2c11249ae66f232311ce5df9d.jpeg | F40: G08 Geel HAANTJES CERTIFISC OUDENAARDE | G40: Speler
...

Sheet Naam-Foto-Ploeg
A1: Naam | B1: Profielfoto | C1: Ploeg | D1: TEAM
A2: {=CHOOSE({1,2,3},'Sorted by Team'!A2:A394,'Sorted by Team'!D2:D394,'Sorted by Team'!F2:F394)} -> Odet Castelain | C2: Balschool U6 | D2: =TRIM(SUBSTITUTE(SUBSTITUTE(SUBSTITUTE(SUBSTITUTE(TRIM(SUBSTITUTE(SUBSTITUTE(SUBSTITUTE(C2," "," "),"HAANTJES CERTIFISC OUDENAARDE",""),"Haantjes CERTIFISC Oudenaarde",""))," Geel","")," Blauw","")," Groen",""),"Haantjes Certifisc Oudenaarde","")) -> Balschool U6
A3: Cécile De Groote Hoebeke | C3: Balschool U6 | D3: =TRIM(SUBSTITUTE(SUBSTITUTE(SUBSTITUTE(SUBSTITUTE(TRIM(SUBSTITUTE(SUBSTITUTE(SUBSTITUTE(C3," "," "),"HAANTJES CERTIFISC OUDENAARDE",""),"Haantjes CERTIFISC Oudenaarde",""))," Geel","")," Blauw","")," Groen",""),"Haantjes Certifisc Oudenaarde","")) -> Balschool U6
A4: Mauro De Leersnyder | C4: Balschool U6 | D4: =TRIM(SUBSTITUTE(SUBSTITUTE(SUBSTITUTE(SUBSTITUTE(TRIM(SUBSTITUTE(SUBSTITUTE(SUBSTITUTE(C4," "," "),"HAANTJES CERTIFISC OUDENAARDE",""),"Haantjes CERTIFISC Oudenaarde",""))," Geel","")," Blauw","")," Groen",""),"Haantjes Certifisc Oudenaarde","")) -> Balschool U6
A5: Rami Decock | C5: Balschool U6 | D5: =TRIM(SUBSTITUTE(SUBSTITUTE(SUBSTITUTE(SUBSTITUTE(TRIM(SUBSTITUTE(SUBSTITUTE(SUBSTITUTE(C5," "," "),"HAANTJES CERTIFISC OUDENAARDE",""),"Haantjes CERTIFISC Oudenaarde",""))," Geel","")," Blauw","")," Groen",""),"Haantjes Certifisc Oudenaarde","")) -> Balschool U6
A6: Jakob Delbaere | C6: Balschool U6 | D6: =TRIM(SUBSTITUTE(SUBSTITUTE(SUBSTITUTE(SUBSTITUTE(TRIM(SUBSTITUTE(SUBSTITUTE(SUBSTITUTE(C6," "," "),"HAANTJES CERTIFISC OUDENAARDE",""),"Haantjes CERTIFISC Oudenaarde",""))," Geel","")," Blauw","")," Groen",""),"Haantjes Certifisc Oudenaarde","")) -> Balschool U6
A7: Cérile Doublet | C7: Balschool U6 | D7: =TRIM(SUBSTITUTE(SUBSTITUTE(SUBSTITUTE(SUBSTITUTE(TRIM(SUBSTITUTE(SUBSTITUTE(SUBSTITUTE(C7," "," "),"HAANTJES CERTIFISC OUDENAARDE",""),"Haantjes CERTIFISC Oudenaarde",""))," Geel","")," Blauw","")," Groen",""),"Haantjes Certifisc Oudenaarde","")) -> Balschool U6
A8: Cas Elyn | C8: Balschool U6 | D8: =TRIM(SUBSTITUTE(SUBSTITUTE(SUBSTITUTE(SUBSTITUTE(TRIM(SUBSTITUTE(SUBSTITUTE(SUBSTITUTE(C8," "," "),"HAANTJES CERTIFISC OUDENAARDE",""),"Haantjes CERTIFISC Oudenaarde",""))," Geel","")," Blauw","")," Groen",""),"Haantjes Certifisc Oudenaarde","")) -> Balschool U6
A9: Tiaz Molly | C9: Balschool U6 | D9: =TRIM(SUBSTITUTE(SUBSTITUTE(SUBSTITUTE(SUBSTITUTE(TRIM(SUBSTITUTE(SUBSTITUTE(SUBSTITUTE(C9," "," "),"HAANTJES CERTIFISC OUDENAARDE",""),"Haantjes CERTIFISC Oudenaarde",""))," Geel","")," Blauw","")," Groen",""),"Haantjes Certifisc Oudenaarde","")) -> Balschool U6
A10: Alba Slembrouck | C10: Balschool U6 | D10: =TRIM(SUBSTITUTE(SUBSTITUTE(SUBSTITUTE(SUBSTITUTE(TRIM(SUBSTITUTE(SUBSTITUTE(SUBSTITUTE(C10," "," "),"HAANTJES CERTIFISC OUDENAARDE",""),"Haantjes CERTIFISC Oudenaarde",""))," Geel","")," Blauw","")," Groen",""),"Haantjes Certifisc Oudenaarde","")) -> Balschool U6
A11: Lily Adam | B11: https://app.twizzit.com/public/photos/2182441/s/eec7946e1a9e80461f26752840c4aedc7d235bab.jpeg | C11: DSE A Haantjes Certifisc Oudenaarde | D11: =TRIM(SUBSTITUTE(SUBSTITUTE(SUBSTITUTE(SUBSTITUTE(TRIM(SUBSTITUTE(SUBSTITUTE(SUBSTITUTE(C11," "," "),"HAANTJES CERTIFISC OUDENAARDE",""),"Haantjes CERTIFISC Oudenaarde",""))," Geel","")," Blauw","")," Groen",""),"Haantjes Certifisc Oudenaarde","")) -> DSE A
A12: Janna Bauters | B12: https://app.twizzit.com/public/photos/2182476/s/d120dcfc0ec82f0d803829f917b4287681f3dd01.png | C12: DSE A Haantjes Certifisc Oudenaarde | D12: =TRIM(SUBSTITUTE(SUBSTITUTE(SUBSTITUTE(SUBSTITUTE(TRIM(SUBSTITUTE(SUBSTITUTE(SUBSTITUTE(C12," "," "),"HAANTJES CERTIFISC OUDENAARDE",""),"Haantjes CERTIFISC Oudenaarde",""))," Geel","")," Blauw","")," Groen",""),"Haantjes Certifisc Oudenaarde","")) -> DSE A
A13: Marie Bourdeaud'hui | B13: https://app.twizzit.com/public/photos/2182516/s/0d7291570c9e5cf142cd892c8fd7ace8c517270a.png | C13: DSE A Haantjes Certifisc Oudenaarde | D13: =TRIM(SUBSTITUTE(SUBSTITUTE(SUBSTITUTE(SUBSTITUTE(TRIM(SUBSTITUTE(SUBSTITUTE(SUBSTITUTE(C13," "," "),"HAANTJES CERTIFISC OUDENAARDE",""),"Haantjes CERTIFISC Oudenaarde",""))," Geel","")," Blauw","")," Groen",""),"Haantjes Certifisc Oudenaarde","")) -> DSE A
A14: Aishatu Lieve Buadee | C14: DSE A Haantjes Certifisc Oudenaarde | D14: =TRIM(SUBSTITUTE(SUBSTITUTE(SUBSTITUTE(SUBSTITUTE(TRIM(SUBSTITUTE(SUBSTITUTE(SUBSTITUTE(C14," "," "),"HAANTJES CERTIFISC OUDENAARDE",""),"Haantjes CERTIFISC Oudenaarde",""))," Geel","")," Blauw","")," Groen",""),"Haantjes Certifisc Oudenaarde","")) -> DSE A
A15: Iris Calewaert | C15: DSE A Haantjes Certifisc Oudenaarde | D15: =TRIM(SUBSTITUTE(SUBSTITUTE(SUBSTITUTE(SUBSTITUTE(TRIM(SUBSTITUTE(SUBSTITUTE(SUBSTITUTE(C15," "," "),"HAANTJES CERTIFISC OUDENAARDE",""),"Haantjes CERTIFISC Oudenaarde",""))," Geel","")," Blauw","")," Groen",""),"Haantjes Certifisc Oudenaarde","")) -> DSE A
